<?xml version="1.0"?>
<robot name="SMALdog">

  <link name="body_link"/>

  <joint name="lf_coxa_joint" type="revolute">
    <axis xyz="1 0 0" />
    <origin xyz="0.086 0.019 0" rpy="0 0 0"/>
    <limit effort="30" lower="-1.57" upper="1.57" velocity="0.5"/>
    <parent link="body_link"/>
    <child link="lf_coxa_link"/>
  </joint>
  <link name="lf_coxa_link">
  </link>
  <joint name="lf_femur_joint" type="revolute">
    <axis xyz="0 1 0" />
    <origin xyz="0 0.050 0" rpy="0 0 0"/>
    <limit effort="30" lower="-1.57" upper="1.57" velocity="0.5"/>
    <parent link="lf_coxa_link"/>
    <child link="lf_femur_link"/>
  </joint>
  <link name="lf_femur_link">
  </link>
  <joint name="lf_tibia_joint" type="revolute">
    <axis xyz="0 1 0" />
    <origin xyz="0 0 -0.064" rpy="0 0 0"/>
    <limit effort="30" lower="-1.57" upper="1.57" velocity="0.5"/>
    <parent link="lf_femur_link"/>
    <child link="lf_tibia_link"/>
  </joint>
  <link name="lf_tibia_link">
    <visual>
      <origin xyz="0.0 0.0 -0.0525" rpy="0 0 0"/>
      <geometry>
        <cylinder radius="0.00635" length="0.105"/>
      </geometry>
    </visual>
  </link>

  <joint name="lr_coxa_joint" type="revolute">
    <axis xyz="1 0 0" />
    <origin xyz="-0.086 0.019 0" rpy="0 0 0"/>
    <limit effort="30" lower="-1.57" upper="1.57" velocity="0.5"/>
    <parent link="body_link"/>
    <child link="lr_coxa_link"/>
  </joint>
  <link name="lr_coxa_link">
  </link>
  <joint name="lr_femur_joint" type="revolute">
    <axis xyz="0 1 0" />
    <origin xyz="0 0.050 0" rpy="0 0 0"/>
    <limit effort="30" lower="-1.57" upper="1.57" velocity="0.5"/>
    <parent link="lr_coxa_link"/>
    <child link="lr_femur_link"/>
  </joint>
  <link name="lr_femur_link">
  </link>
  <joint name="lr_tibia_joint" type="revolute">
    <axis xyz="0 1 0" />
    <origin xyz="0 0 -0.064" rpy="0 0 0"/>
    <limit effort="30" lower="-1.57" upper="1.57" velocity="0.5"/>
    <parent link="lr_femur_link"/>
    <child link="lr_tibia_link"/>
  </joint>
  <link name="lr_tibia_link">
    <visual>
      <origin xyz="0.0 0.0 -0.0525" rpy="0 0 0"/>
      <geometry>
        <cylinder radius="0.00635" length="0.105"/>
      </geometry>
    </visual>
  </link>

  <joint name="rf_coxa_joint" type="revolute">
    <axis xyz="1 0 0" />
    <origin xyz="0.086 -0.019 0" rpy="0 0 0"/>
    <limit effort="30" lower="-1.57" upper="1.57" velocity="0.5"/>
    <parent link="body_link"/>
    <child link="rf_coxa_link"/>
  </joint>
  <link name="rf_coxa_link">
  </link>
  <joint name="rf_femur_joint" type="revolute">
    <axis xyz="0 1 0" />
    <origin xyz="0 -0.050 0" rpy="0 0 0"/>
    <limit effort="30" lower="-1.57" upper="1.57" velocity="0.5"/>
    <parent link="rf_coxa_link"/>
    <child link="rf_femur_link"/>
  </joint>
  <link name="rf_femur_link">
  </link>
  <joint name="rf_tibia_joint" type="revolute">
    <axis xyz="0 1 0" />
    <origin xyz="0 0 -0.064" rpy="0 0 0"/>
    <limit effort="30" lower="-1.57" upper="1.57" velocity="0.5"/>
    <parent link="rf_femur_link"/>
    <child link="rf_tibia_link"/>
  </joint>
  <link name="rf_tibia_link">
    <visual>
      <origin xyz="0.0 0.0 -0.0525" rpy="0 0 0"/>
      <geometry>
        <cylinder radius="0.00635" length="0.105"/>
      </geometry>
    </visual>
  </link>

  <joint name="rr_coxa_joint" type="revolute">
    <axis xyz="1 0 0" />
    <origin xyz="-0.086 -0.019 0" rpy="0 0 0"/>
    <limit effort="30" lower="-1.57" upper="1.57" velocity="0.5"/>
    <parent link="body_link"/>
    <child link="rr_coxa_link"/>
  </joint>
  <link name="rr_coxa_link">
  </link>
  <joint name="rr_femur_joint" type="revolute">
    <axis xyz="0 1 0" />
    <origin xyz="0 -0.050 0" rpy="0 0 0"/>
    <limit effort="30" lower="-1.57" upper="1.57" velocity="0.5"/>
    <parent link="rr_coxa_link"/>
    <child link="rr_femur_link"/>
  </joint>
  <link name="rr_femur_link">
  </link>
  <joint name="rr_tibia_joint" type="revolute">
    <axis xyz="0 1 0" />
    <origin xyz="0 0 -0.064" rpy="0 0 0"/>
    <limit effort="30" lower="-1.57" upper="1.57" velocity="0.5"/>
    <parent link="rr_femur_link"/>
    <child link="rr_tibia_link"/>
  </joint>
  <link name="rr_tibia_link">
    <visual>
      <origin xyz="0.0 0.0 -0.0525" rpy="0 0 0"/>
      <geometry>
        <cylinder radius="0.00635" length="0.105"/>
      </geometry>
    </visual>
  </link>

</robot>
